Workbook
Name Big_Blue: carters!$E$2:$E$8
Name Carter: carters!$A$2:$A$7
Name Coreless: carters!$D$2:$D$7
Name EMS_03: carters!$F$3:$F$15
Name EMS_05: carters!$G$2:$G$15
Name PCY_27: carters!$I$2:$I$6
Name Standard: carters!$H$2:$H$15

Sheet Installation
A1: TTE / FICHE NOUVEAU SITE | K1: Feuille à remplir par le Chargé d'Affaires
A2: MàJ 30/10/2025
A3: Client : | F3: Code client : | G3: N° Affaire : | H3: T | K3: Cellules en vert : | L3: à saisir
K4: Cellules en jaune : | L4: liste déroulante
A5: Adresse : | E5: Prix d'achat TTE : | G5: Type :
A6: installation TTE | K6: Pensez à vérifier la cohérence des réf. et quantités à fournir sur les onglets Consos MeS et REV_AN !
E7: Prix de vente TTE : | G7: Installateur :
I8: Herco therm :
F9: N° Herco : | G9: Prix d'achat : | H9: Date achat : | O9: Raccords | P9: 00466039
A10: Osmoseur 1 : | F10: AF | O10: =IF(ISBLANK(B10),0,2) -> 0
A11: Osmoseur 2 : | F11: AF | K11: NE PAS TOUCHER LES FORMULES SUR LES DIFFERENTS ONGLETS !!! | O11: =IF(ISBLANK(B11),0,2) -> 0
A12: Osmoseur 3 : | F12: AF
A13: Consommables à livrer avant le : | F13: Répartiteur : | I13: Résistance intermédiaire : | O13: Embouts | P13: EMBPEX25-21
C14: ===> @ :
A16: Garantie : | F16: Date prévue de mise en service :
A17: Maint. préventive : | F17: Date signature QI/QO :
A18: Consommables : | G18: Technicien référent :
A20: Spécificités :
A23: Prétraitement
B24: Surpresseur : | G24: H²Observer Prétraitement | I24: OUI
A26: Colonne FAS | F26: Colonne CAG | G26: 80L - 14x65 - Performa 273/742F
B27: Nbre bouteilles | G27: Nbre bouteilles
F28: ou :
A29: Etage 0 | B29: Carter | F29: Etage 3 | G29: Carter
A30: (Coreless) | B30: Nbre de carter | F30: (CA) | G30: Nbre de carter
B31: Filtre | G31: Filtre
A33: Etage 1 | B33: Carter | C33: Big_Blue | F33: Etage 4 | G33: Carter | H33: Standard
A34: (Nominal) | B34: Nbre de carter | C34: 2 | F34: (Absolu) | G34: Nbre de carter | H34: 2
B35: Filtre | C35: BB DGD 50-5µm | G35: Filtre | H35: 1 µm absolu
A37: Etage 2 | B37: Carter | C37: Standard | F37: Testomat 2 | G37: n/a
A38: (Nominal) | B38: Nbre de carter | C38: 2 | F38: (Chlore)
B39: Filtre | C39: 5µm nominal
F40: Filtration boucle
A41: Colonne Adou. | B41: 25L - 8x44 - Performa 278 CV/764 | F41: Nbre de carter | H41: 1
B42: Nbre bouteilles | C42: 2
F43: Module production acide | H43: NON
A44: Capteur dureté Limitron | C44: NON | F44: Distribution concentré
A45: ou : | F45: Nbre de cuves stockage
A46: Testomat 1 | B46: STD (100.097) => TH | F46: CeCon 3000 | H46: Date achat :
A47: (Dureté) | F47: N° de série :
...

Sheet Consos MeS
D1: =Installation!H3 -> T | E1: =Installation!A1 -> TTE / FICHE NOUVEAU SITE | G1: =Installation!F4 -> 0
E3: Consommables pour mise en service | F3: LV avant le : | H3: =Installation!B14 -> 0
G4: chez : | H4: =Installation!D14 -> 0
A6: Filtre | B6: Postes | D6: Réf. | E6: Désignation | F6: Qté | G6: PR | H6: Coût
A7: =Installation!C31 -> 0 | B7: {=_xlfn.IFS(ISBLANK(Installation!C29),"0",Installation!C29="EMS_03","3",Installation!C29="EMS_05","5",TRUE,"1")} -> 0 | C7: 0 | D7: =VLOOKUP(A7,filtres!A$2:I$101,2,FALSE) -> #N/A | E7: =VLOOKUP(D7,filtres!B$2:I$101,2,FALSE) -> #N/A | F7: =Installation!C30*B7 -> 0 | G7: =VLOOKUP(D7,filtres!B$2:I$101,7,FALSE) -> #N/A | H7: =F7*G7 -> #N/A
A8: =Installation!C35 -> BB DGD 50-5µm | B8: {=_xlfn.IFS(ISBLANK(Installation!C33),"0",Installation!C33="EMS_03","3",Installation!C33="EMS_05","5",TRUE,"1")} -> 1 | C8: 1 | D8: =VLOOKUP(A8,filtres!A$2:I$101,2,FALSE) -> FILDGD20BB505 | E8: =VLOOKUP(D8,filtres!B$2:I$101,2,FALSE) -> Pentair DGD 20" Big Blue 50-5µm (73070) | F8: =Installation!C34*B8 -> 2 | G8: =VLOOKUP(D8,filtres!B$2:I$101,7,FALSE) -> 17.84 | H8: =F8*G8 -> 35.68
A9: =Installation!C39 -> 5µm nominal | B9: {=_xlfn.IFS(ISBLANK(Installation!C37),"0",Installation!C37="EMS_03","3",Installation!C37="EMS_05","5",TRUE,"1")} -> 1 | C9: 2 | D9: =VLOOKUP(A9,filtres!A$2:I$101,2,FALSE) -> FILNOM205 | E9: =VLOOKUP(D9,filtres!B$2:I$101,2,FALSE) -> KlariSpunGA Crystal 20" 5µm DOE (nominal) (97206) | F9: =Installation!C38*B9 -> 2 | G9: =VLOOKUP(D9,filtres!B$2:I$101,7,FALSE) -> 3.97 | H9: =F9*G9 -> 7.94
A10: =Installation!H31 -> 0 | B10: {=_xlfn.IFS(ISBLANK(Installation!H29),"0",Installation!H29="EMS_03","3",Installation!H29="EMS_05","5",TRUE,"1")} -> 0 | C10: 3 | D10: =VLOOKUP(A10,filtres!A$2:I$101,2,FALSE) -> #N/A | E10: =VLOOKUP(D10,filtres!B$2:I$101,2,FALSE) -> #N/A | F10: =Installation!H30*B10 -> 0 | G10: =VLOOKUP(D10,filtres!B$2:I$101,7,FALSE) -> #N/A | H10: =F10*G10 -> #N/A
A11: =Installation!H35 -> 1 µm absolu | B11: {=_xlfn.IFS(ISBLANK(Installation!H33),"0",Installation!H33="EMS_03","3",Installation!H33="EMS_05","5",TRUE,"1")} -> 1 | C11: 4 | D11: =VLOOKUP(A11,filtres!A$2:I$101,2,FALSE) -> FILABS201 | E11: =VLOOKUP(D11,filtres!B$2:I$101,2,FALSE) -> KlariSpunGA Excel 20'' 1µm DOE EPDM (absolu) (97306) | F11: =Installation!H34*B11 -> 2 | G11: =VLOOKUP(D11,filtres!B$2:I$101,7,FALSE) -> 22.29 | H11: =F11*G11 -> 44.58
A12: boucle | B12: =Installation!H41 -> 1 | C12: B | D12: =VLOOKUP(A12,filtres!A$2:I$101,2,FALSE) -> FILBOU2002B-7S | E12: =VLOOKUP(D12,filtres!B$2:I$101,2,FALSE) -> EfilPore PESGA 20" 0,2µm abs. Code 7S grade bio (97005) 2x226+baïonnette | F12: =Installation!H41 -> 1 | G12: =VLOOKUP(D12,filtres!B$2:I$101,7,FALSE) -> 194.75 | H12: =F12*G12 -> 194.75
C14: Analyses | D14: 152.025 | E14: =VLOOKUP(D14,filtres!B$2:I$101,2,FALSE) -> Réactif Testomat TH (dureté) 2025 - 500 ml | F14: =(IF(OR(Installation!B46="STD (100.097) => TH",Installation!B46="THCL (100.282) => TH+CLT",Installation!B46="STD SelfClean (100.372) => TH"),1,0))+(IF(OR(Installation!G37="STD (100.097) => TH",Installation!G37="THCL (100.282) => TH+CLT",Installation!G37="STD SelfClean (100.372) => TH"),1,0)) -> 1 | G14: =VLOOKUP(D14,filtres!B$2:I$101,7,FALSE) -> 94.044 | H14: =F14*G14 -> 94.044
D15: 156.237 | E15: =VLOOKUP(D15,filtres!B$2:I$101,2,FALSE) -> Kit Réactifs Testomat CL A-B-C (total) pour 1200 analyses | F15: =(IF(OR(Installation!B46="THCL (100.282) => TH+CLT",Installation!B46="CLT SelfClean (100.247) => CLT"),1,0))+(IF(OR(Installation!G37="THCL (100.282) => TH+CLT",Installation!G37="CLT SelfClean (100.247) => CLT"),1,0)) -> 0 | G15: =VLOOKUP(D15,filtres!B$2:I$101,7,FALSE) -> 134.64 | H15: =F15*G15 -> 0
D16: 151.105 | E16: =VLOOKUP(D16,filtres!B$2:I$101,2,FALSE) -> Réactif Nettoyant/Désinfectant SelfClean pour Testomat 2000 (500ml) | F16: =(IF(OR(Installation!B46="STD SelfClean (100.372) => TH",Installation!B46="CLT SelfClean (100.247) => CLT"),1,0))+(IF(OR(Installation!G37="STD SelfClean (100.372) => TH",Installation!G37="CLT SelfClean (100.247) => CLT"),1,0)) -> 0 | G16: =VLOOKUP(D16,filtres!B$2:I$101,7,FALSE) -> 63.24 | H16: =F16*G16 -> 0
D17: ORMCD1003 | E17: =VLOOKUP(D17,filtres!B$2:I$101,2,FALSE) -> Kit analyse dureté TH flacon unique 20ml pour eau de réseau (1goutte = 1°F) | F17: =IF(Installation!C54="OUI",1,0) -> 1 | G17: =VLOOKUP(D17,filtres!B$2:I$101,7,FALSE) -> 14.986 | H17: =F17*G17 -> 14.986
D18: 00535114 | E18: =VLOOKUP(D18,filtres!B$2:I$101,2,FALSE) -> Test colorimétrique VISOCOLOR HE Chlore pour concentrations faibles (160 tests) / 920015 | F18: =IF(Installation!C55="OUI",1,0) -> 1 | G18: =VLOOKUP(D18,filtres!B$2:I$101,7,FALSE) -> 125.51 | H18: =F18*G18 -> 125.51
D19: 00630079 | E19: =VLOOKUP(D19,filtres!B$2:I$101,2,FALSE) -> Test Quantofix Peroxyde 100 (100 languettes test semi-quantitatives) / 91312 | F19: =IF(Installation!C58="OUI",1,0) -> 1 | G19: =VLOOKUP(D19,filtres!B$2:I$101,7,FALSE) -> 32.67 | H19: =F19*G19 -> 32.67
D20: DIALOXACTIVE5L | E20: =VLOOKUP(D20,filtres!B$2:I$101,2,FALSE) -> Dialox Active 5L ref. 104149 (Désinfectant acide péracétique 1%) | F20: =IF(Installation!C57="OUI",1,0) -> 1 | G20: =VLOOKUP(D20,filtres!B$2:I$101,7,FALSE) -> 77.688 | H20: =F20*G20 -> 77.688
D22: SL7-100-L-RYG-24LED | E22: =VLOOKUP(D22,filtres!B$2:I$101,2,FALSE) -> Colonne lumineuse à LED feu fixe R/J/V 24 V série SL7 | F22: =IF(Installation!H50="OUI",Installation!I50,0) -> 0 | G22: =VLOOKUP(D22,filtres!B$2:I$101,7,FALSE) -> 235.1 | H22: =F22*G22 -> 0
D23: SL7-L24-B | E23: =VLOOKUP(D23,filtres!B$2:I$101,2,FALSE) -> LED flash fixe Bleu pour colonne lumineuse 24 V série SL7 | F23: =IF(Installation!H52="OUI",Installation!I51,0) -> 0 | G23: =VLOOKUP(D23,filtres!B$2:I$101,7,FALSE) -> 63.5 | H23: =F23*G23 -> 0
D24: SL7-CB-FW | E24: Module de base pour montage vertical 1 côté colonne lumineuse 24 V série SL7 | F24: =IF(Installation!H52="OUI",Installation!I52,0) -> 0 | G24: =VLOOKUP(D24,filtres!B$2:I$101,7,FALSE) -> 53.81 | H24: =F24*G24 -> 0
D25: 600524 | E25: =VLOOKUP(D25,filtres!B$2:I$101,2,FALSE) -> Système Ares SMS | F25: =IF(Installation!H53="OUI",Installation!I53,0) -> 0 | G25: =VLOOKUP(D25,filtres!B$2:I$101,7,FALSE) -> 394.1192 | H25: =F25*G25 -> 0
D26: 4C.02.9.024.0050SPA | E26: Relais d'interface Finder 24V c.c., 2 RT, montage Rail DIN, série , 4C Series | F26: =IF(Installation!H54="OUI",Installation!I54,0) -> 0 | G26: =VLOOKUP(D26,filtres!B$2:I$101,7,FALSE) -> 18.39 | H26: =F26*G26 -> 0
D27: SP006-0-SL009-01-4 | E27: =VLOOKUP(D27,filtres!B$2:I$101,2,FALSE) -> Raccord d'alimentation inox Walther femelle douille cannelée 9mm (générateur) | F27: =IF(Installation!H54="OUI",Installation!I55,0) -> 0 | G27: =VLOOKUP(D27,filtres!B$2:I$101,7,FALSE) -> 173.42 | H27: =F27*G27 -> 0
C29: CeCon3000 | D29: ZG05SI021 | E29: =VLOOKUP(D29,filtres!B$2:I$101,2,FALSE) -> Tuyau silicone OD 14.4x3.2 blanc (le m., par couronne de 25 m) (CeCon 3000) | F29: =Installation!D62 -> 0 | G29: =VLOOKUP(D29,filtres!B$2:I$101,7,FALSE) -> 17.19165 | H29: =F29*G29 -> 0
D30: ZG17PP954 | E30: =VLOOKUP(D30,filtres!B$2:I$101,2,FALSE) -> Connecteur en T, PP 7,9 mm (CeCon 3000) | F30: =Installation!D63 -> 0 | G30: =VLOOKUP(D30,filtres!B$2:I$101,7,FALSE) -> 2.4301305 | H30: =F30*G30 -> 0
D31: ZG05V9416 | E31: =VLOOKUP(D31,filtres!B$2:I$101,2,FALSE) -> Clip 16.5, inox (CeCon 3000) | F31: =Installation!D64 -> 0 | G31: =VLOOKUP(D31,filtres!B$2:I$101,7,FALSE) -> 1.87425 | H31: =F31*G31 -> 0
D32: DN50FX8 | E32: =VLOOKUP(D32,filtres!B$2:I$101,2,FALSE) -> DN50 F pour tuyau 8 mm (raccords BIB / CeCon 3000) | F32: =Installation!D65 -> 0 | G32: =VLOOKUP(D32,filtres!B$2:I$101,7,FALSE) -> 66.74 | H32: =F32*G32 -> 0
G33: Total : | H33: =SUM(H7:H32) -> #N/A
D35: A fournir en plus pour la mise en service :

Sheet REV_AN
B2: Kit maintenance
C3: annuelle
B4: Traitement d'eau
A6: =Installation!A1 -> TTE / FICHE NOUVEAU SITE
A8: =Installation!F4 -> 0 | C8: Mise en service :
B9: =Installation!F10 -> AF | C9: =Installation!H16 -> 0
B11: Désignation | C11: Référence | D11: Qté | F11: PR unitaire | G11: Coût
A12: Carters pré-filtration
A13: 0 | B13: =VLOOKUP(C13,filtres!B$2:I$101,2,FALSE) -> #N/A | C13: {=_xlfn.IFS(ISBLANK(Installation!C29),"n/a",Installation!C29="Coreless","ACS44EX",Installation!C29="Big_Blue","73190",Installation!C29="Standard","73197",Installation!C29="EMS_03","ACS39EX",Installation!C29="EMS_05","ACS44EX",Installation!C29="PCY_27","GK1344PX01",TRUE,"n/a")} -> n/a | D13: =Installation!C30 -> 0 | F13: =VLOOKUP(C13,filtres!B$2:I$101,7,FALSE) -> #N/A | G13: =D13*F13 -> #N/A
A14: 1 | B14: =VLOOKUP(C14,filtres!B$2:I$101,2,FALSE) -> Joint torique Buna-N pour carters Big Blue, cartouches & poches (réf 151122) | C14: {=_xlfn.IFS(ISBLANK(Installation!C33),"n/a",Installation!C33="Coreless","ACS44EX",Installation!C33="Big_Blue","73190",Installation!C33="Standard","73197",Installation!C33="EMS_03","ACS39EX",Installation!C33="EMS_05","ACS44EX",Installation!C33="PCY_27","GK1344PX01",TRUE,"n/a")} -> 73190 | D14: =Installation!C34 -> 2 | F14: =VLOOKUP(C14,filtres!B$2:I$101,7,FALSE) -> 6.66 | G14: =D14*F14 -> 13.32
A15: 2 | B15: =VLOOKUP(C15,filtres!B$2:I$101,2,FALSE) -> Joint torique EPDM pour carters Standard & 3G (ref 151120) | C15: {=_xlfn.IFS(ISBLANK(Installation!C37),"n/a",Installation!C37="Coreless","ACS44EX",Installation!C37="Big_Blue","73190",Installation!C37="Standard","73197",Installation!C37="EMS_03","ACS39EX",Installation!C37="EMS_05","ACS44EX",Installation!C37="PCY_27","GK1344PX01",TRUE,"n/a")} -> 73197 | D15: =Installation!C38 -> 2 | F15: =VLOOKUP(C15,filtres!B$2:I$101,7,FALSE) -> 2.67 | G15: =D15*F15 -> 5.34
A16: 3 | B16: =VLOOKUP(C16,filtres!B$2:I$101,2,FALSE) -> #N/A | C16: {=_xlfn.IFS(ISBLANK(Installation!H29),"n/a",Installation!H29="Coreless","ACS44EX",Installation!H29="Big_Blue","73190",Installation!H29="Standard","73197",Installation!H29="EMS_03","ACS39EX",Installation!H29="EMS_05","ACS44EX",Installation!H29="PCY_27","GK1344PX01",TRUE,"n/a")} -> n/a | D16: =Installation!H30 -> 0 | F16: =VLOOKUP(C16,filtres!B$2:I$101,7,FALSE) -> #N/A | G16: =D16*F16 -> #N/A
A17: 4 | B17: =VLOOKUP(C17,filtres!B$2:I$101,2,FALSE) -> Joint torique EPDM pour carters Standard & 3G (ref 151120) | C17: {=_xlfn.IFS(ISBLANK(Installation!H33),"n/a",Installation!H33="Coreless","ACS44EX",Installation!H33="Big_Blue","73190",Installation!H33="Standard","73197",Installation!H33="EMS_03","ACS39EX",Installation!H33="EMS_05","ACS44EX",Installation!H33="PCY_27","GK1344PX01",TRUE,"n/a")} -> 73197 | D17: =Installation!H34 -> 2 | F17: =VLOOKUP(C17,filtres!B$2:I$101,7,FALSE) -> 2.67 | G17: =D17*F17 -> 5.34
A18: Analyseurs
B19: =VLOOKUP(C19,filtres!B$2:I$101,2,FALSE) -> #N/A | C19: =IF(Installation!C44="OUI","00370031","n/a") -> n/a | D19: =IF(Installation!C44="OUI","1","0") -> 0 | F19: =VLOOKUP(C19,filtres!B$2:I$101,7,FALSE) -> #N/A | G19: =D19*F19 -> #N/A
A20: 1 | B20: =VLOOKUP(C20,filtres!B$2:I$101,2,FALSE) -> Kit entretien annuel pour T2000/ECO (1P) | C20: {=_xlfn.IFS(ISBLANK(Installation!B46),"n/a",Installation!B46="STD (100.097) => TH","040.901",Installation!B46="THCL (100.282) => TH+CLT","040.904",Installation!B46="STD SelfClean (100.372) => TH","040.902",Installation!B46="CLT SelfClean (100.247) => CLT","040.904",TRUE,"n/a")} -> 040.901 | D20: =IF(C20="n/a","0",1) -> 1 | F20: =VLOOKUP(C20,filtres!B$2:I$101,7,FALSE) -> 173.4 | G20: =D20*F20 -> 173.4
A21: 2 | B21: =VLOOKUP(C21,filtres!B$2:I$101,2,FALSE) -> #N/A | C21: {=_xlfn.IFS(ISBLANK(Installation!G37),"n/a",Installation!G37="STD (100.097) => TH","040.901",Installation!G37="THCL (100.282) => TH+CLT","040.904",Installation!G37="STD SelfClean (100.372) => TH","040.902",Installation!G37="CLT SelfClean (100.247) => CLT","040.904",TRUE,"n/a")} -> n/a | D21: =IF(C21="n/a","0",1) -> 0 | F21: =VLOOKUP(C21,filtres!B$2:I$101,7,FALSE) -> #N/A | G21: =D21*F21 -> #N/A
A22: Membranes Prises d'échantillons
B23: =VLOOKUP(C23,filtres!B$2:I$101,2,FALSE) -> #N/A | C23: =IF(ISBLANK(Installation!C50),"n/a","JM05301") -> n/a | D23: =Installation!C50 -> 0 | F23: =VLOOKUP(C23,filtres!B$2:I$101,7,FALSE) -> #N/A | G23: =D23*F23 -> #N/A
B24: =VLOOKUP(C24,filtres!B$2:I$101,2,FALSE) -> Membrane silicone pour PEMS II, III & VII (DN06) (chaleur) | C24: =IF(ISBLANK(Installation!C51),"n/a","JM05601") -> JM05601 | D24: =Installation!C51 -> 5 | F24: =VLOOKUP(C24,filtres!B$2:I$101,7,FALSE) -> 6.82 | G24: =D24*F24 -> 34.1
A25: Banc filtration stérilisante 0,2µm
B26: =VLOOKUP(C26,filtres!B$2:I$101,2,FALSE) -> EfilPore PESGA 20" 0,2µm abs. Code 7S grade bio (97005) 2x226+baïonnette | C26: {=_xlfn.IFS(ISBLANK(Installation!H41),"n/a",TRUE,"FILBOU2002B-7S")} -> FILBOU2002B-7S | D26: N/A
B27: =VLOOKUP(C27,filtres!B$2:I$101,2,FALSE) -> Joint silicone support cloche carter inox boucle type PLT12 | C27: {=_xlfn.IFS(ISBLANK(Installation!H41),"n/a",TRUE,"GK1242QL01")} -> GK1242QL01 | D27: =Installation!H41 -> 1 | F27: =VLOOKUP(C27,filtres!B$2:I$101,7,FALSE) -> 22 | G27: =D27*F27 -> 22
B28: =VLOOKUP(C28,filtres!B$2:I$101,2,FALSE) -> Joint silicoene micro clamp d25 pour tube d13.5 évent carter inox 0,2 >>> JCSIL127217 | C28: {=_xlfn.IFS(OR(ISBLANK(Installation!H41),Installation!H43="OUI"),"n/a",TRUE,"CLP-MICRO-JNT13.5")} -> CLP-MICRO-JNT13.5 | D28: =IF(OR(Installation!H43="NON",ISBLANK(Installation!H43)),Installation!H41,"0") -> 1 | F28: =VLOOKUP(C28,filtres!B$2:I$101,7,FALSE) -> 11.7 | G28: =D28*F28 -> 11.7
B29: =VLOOKUP(C29,filtres!B$2:I$101,2,FALSE) -> #N/A | C29: {=_xlfn.IFS(ISBLANK(Installation!H43),"n/a",Installation!H43="NON","n/a",TRUE,"JCSIL254504")} -> n/a | D29: =IF(Installation!H43="OUI",Installation!H41,"0")*3 -> 0 | F29: =VLOOKUP(C29,filtres!B$2:I$101,7,FALSE) -> #N/A | G29: =D29*F29 -> #N/A
B30: =VLOOKUP(C30,filtres!B$2:I$101,2,FALSE) -> #N/A | C30: {=_xlfn.IFS(ISBLANK(Installation!H43),"n/a",Installation!H43="NON","n/a",TRUE,"JCSIL127217")} -> n/a | D30: =IF(Installation!H43="OUI",Installation!H41,"0")*3 -> 0 | F30: =VLOOKUP(C30,filtres!B$2:I$101,7,FALSE) -> #N/A | G30: =D30*F30 -> #N/A
B31: =VLOOKUP(C31,filtres!B$2:I$101,2,FALSE) -> #N/A | C31: {=_xlfn.IFS(ISBLANK(Installation!H43),"n/a",Installation!H43="NON","n/a",TRUE,"MEPDMVMI1")} -> n/a | D31: =IF(Installation!H43="OUI",Installation!H41,"0")*3 -> 0 | F31: =VLOOKUP(C31,filtres!B$2:I$101,7,FALSE) -> #N/A | G31: =D31*F31 -> #N/A
A32: Distribution concentré
B33: =VLOOKUP(C33,filtres!B$2:I$101,2,FALSE) -> #N/A | C33: =IF(Installation!H44="OUI","FILEVC05001","n/a") -> n/a | D33: =IF(Installation!H44="OUI",Installation!H45,"0") -> 0 | F33: =VLOOKUP(C33,filtres!B$2:I$101,7,FALSE) -> #N/A | G33: =D33*F33 -> #N/A
F35: Total : | G35: =SUM(G13:G33) -> #N/A

Sheet REV_SEM
B2: Kit maintenance
C3: semestrielle
B4: Traitement d'eau
A6: =Installation!A1 -> TTE / FICHE NOUVEAU SITE
A8: =Installation!F4 -> 0 | C8: Mise en service :
C9: =Installation!H16 -> 0
B11: Désignation | C11: Référence | D11: Qté | F11: PR unitaire | G11: Coût
A12: Banc filtration stérilisante 0,2µm
B13: =VLOOKUP(C13,filtres!B$2:I$101,2,FALSE) -> #N/A | C13: {=_xlfn.IFS(ISBLANK(Installation!H28),"n/a",TRUE,"FILBOU2002B-7S")} -> n/a | D13: N/A
B14: =VLOOKUP(C14,filtres!B$2:I$101,2,FALSE) -> Joint silicone support cloche carter inox boucle type PLT12 | C14: {=_xlfn.IFS(ISBLANK(Installation!H41),"n/a",TRUE,"GK1242QL01")} -> GK1242QL01 | D14: =Installation!H41 -> 1 | F14: =VLOOKUP(C14,filtres!B$2:I$101,9,FALSE) -> #REF! | G14: =D14*F14 -> #REF!
B15: =VLOOKUP(C15,filtres!B$2:I$101,2,FALSE) -> Joint silicoene micro clamp d25 pour tube d13.5 évent carter inox 0,2 >>> JCSIL127217 | C15: {=_xlfn.IFS(OR(ISBLANK(Installation!H41),Installation!H43="OUI"),"n/a",TRUE,"CLP-MICRO-JNT13.5")} -> CLP-MICRO-JNT13.5 | D15: =IF(OR(Installation!H43="NON",ISBLANK(Installation!H43)),Installation!H41,"0") -> 1 | F15: =VLOOKUP(C15,filtres!B$2:I$101,9,FALSE) -> #REF! | G15: =D15*F15 -> #REF!
B16: =VLOOKUP(C16,filtres!B$2:I$101,2,FALSE) -> #N/A | C16: {=_xlfn.IFS(ISBLANK(Installation!H43),"n/a",Installation!H43="NON","n/a",TRUE,"JCSIL254504")} -> n/a | D16: =IF(Installation!H43="OUI",Installation!H41,"0")*3 -> 0 | F16: =VLOOKUP(C16,filtres!B$2:I$101,9,FALSE) -> #N/A | G16: =D16*F16 -> #N/A
B17: =VLOOKUP(C17,filtres!B$2:I$101,2,FALSE) -> #N/A | C17: {=_xlfn.IFS(ISBLANK(Installation!H43),"n/a",Installation!H43="NON","n/a",TRUE,"JCSIL127217")} -> n/a | D17: =IF(Installation!H43="OUI",Installation!H41,"0")*3 -> 0 | F17: =VLOOKUP(C17,filtres!B$2:I$101,9,FALSE) -> #N/A | G17: =D17*F17 -> #N/A
B18: =VLOOKUP(C18,filtres!B$2:I$101,2,FALSE) -> #N/A | C18: {=_xlfn.IFS(ISBLANK(Installation!H43),"n/a",Installation!H43="NON","n/a",TRUE,"MEPDMVMI1")} -> n/a | D18: =IF(Installation!H43="OUI",Installation!H41,"0")*3 -> 0 | F18: =VLOOKUP(C18,filtres!B$2:I$101,9,FALSE) -> #N/A | G18: =D18*F18 -> #N/A
F20: Total : | G20: =SUM(G12:G18) -> #REF!

Sheet listes
A1: HP5500D 300 P/H (1) | B1: DR | C1: n/a | D1: 9kW | E1: VENTE | F1: 2 ans pièces et MO (5 ans membranes) | G1: 1 an | H1: Non inclus / Garantie soumie à achat consos | I1: NON | J1: NON | K1: 2 | L1: 1 | M1: 1 | N1: N/A | O1: NON | P1: Aseptic | Q1: Walther SP006 d.9mm (SL009) | R1: NON | S1: 1formule/1étage | T1: n/a | U1: 50m | V1: Site client | W1: Type CPC | X1: Cuve vrac
A2: HP5500D 500 P/H (2+2) | B2: STD | C2: STD (100.097) => TH | D2: 18kW | E2: LOCATION | F2: 2 ans pièces et MO (3 ans membranes) | G2: 2 ans | H2: Non inclus (payants, sur commande) | I2: 1 | J2: 1 | K2: 4 | L2: 2 | M2: 2 | N2: 25L - 8x44 - Performa 278 CV/764 | O2: OUI | P2: E.C.O. | Q2: Walther SP006 d.6mm (SL006) | R2: Centrale HERCO | S2: 2formules/1étage | T2: Simplex CRIE 3-5 | U2: 100m | V2: TLS (CPU) | W2: Inox | X2: BIB
A3: HP5500D 750 P/H (3+3) | B3: WBO | C3: STD SelfClean (100.372) => TH | E3: PACK | F3: 1 an pièces et MO (5 ans membranes) | G3: 3 ans | H3: Inclus sous contrat (cadencier) | I3: 2 | J3: 2 | K3: 6 | L3: 3 | M3: 3 | N3: 50L - 10x54 - Performa 278 CV/764 | P3: Hemotech | Q3: Staubli RBE06 | S3: 3formules/1étage | T3: Simplex CRIE 5-5 | U3: 150m | V3: TLS (TWA)
A4: HP5500D 1000 P/H (4+4) | C4: THCL (100.282) => TH+CLT | F4: 1 an pièces et MO (3 ans membranes) | G4: Non inclus (payant) | I4: 3 | L4: 4 | M4: 4 | N4: 75L - 13x54 - Performa 278 CV/764 | Q4: Staubli RBE08 | S4: 1formule/2étages | T4: Duplex CRIE 3-5 | U4: 200m | V4: DPD DR
A5: HP5500D 1250 P/H (5+5) | B5: AK | C5: CLT SelfClean (100.247) => CLT | F5: 1 an pièces (5 ans membranes) hors MO | I5: 4 | L5: 5 | M5: 5 | N5: 100L - 14x65 - Performa 278 CV/764 | S5: 2formules/2étages | T5: Duplex CRIE 5-5 | U5: 250m | V5: DPD OBA
A6: HP5500D 1500 P/H (6+6) | B6: DCR | F6: 1 an pièces (3 ans membranes) hors MO | L6: 6 | M6: 6 | N6: 150L - 16x65 - Performa 278 CV/764 | S6: 1formules/3étages | T6: Duplex CRIE 10-5 | U6: 300m | V6: DPD STD
A7: HP5500D 2000 P/H (8+8) | B7: DR | F7: 1 an pièces hors MO | L7: 7 | M7: 7 | N7: 200L - 18x65 - Performa 278 CV/764 | V7: DPD WBO
A8: HP5500D 2500 P/H (2+2 / 8") | B8: FLA | C8: n/a | L8: 8 | M8: 8 | N8: N/A | V8: DPD FLA
A9: HP5500D 3500 P/H (3+3 / 8") | B9: GCH | C9: THCL (100.282) => TH+CLT | M9: 9 | N9: 50L - 13x54 - Performa 273/742F | V9: DPD GCH
A10: HP5500D 4500 P/H (4+4 / 8") | B10: JBO | C10: CLT SelfClean (100.247) => CLT | M10: 10 | N10: 80L - 14x65 - Performa 273/742F | V10: DPD JBO
A11: HP5500D 650 P (2+2) | B11: JTO | N11: 90L - 16x65 - Performa 273/742F | V11: DPD JTO
A12: HP5500D 1000 P (3+3) | B12: LL | N12: 120L - 18x65 - Performa 273/742F | V12: DPD LL
A13: HP5500D 1350 P (4+4) | B13: MMA | V13: DPD MMA
A14: HP5500D 1700 P (5+5) | B14: NBL | N14: N/A | V14: DPD NBL
A15: HP5500D 300 L/H (1) | B15: KTA | N15: 42L - 10x54 - Performa 273/742F | V15: DPD KTA
A16: HP5500D 600 L/H (2) | B16: OBA | N16: 67L - 13x54 - Performa 273/742F | V16: DPD TC
A17: HP5500D 900 L/H (3) | B17: STD | N17: 85L - 14x65 - Performa 273/742F | V17: DPD TMA
A18: HP5500D 1200 L/H (4) | B18: TC | N18: 112L - 16x65 - Performa 273/742F
A19: HP5500D 1500 L/H (5) | B19: TMA | N19: 142L - 18x65 - Performa 273/742F
B20: WBO

Sheet filtres
F1: PA | G1: FA | H1: PR | I1: Validité
B2: FILBOU1002N-3S | C2: =VLOOKUP(B2,[1]BDD!$A$4:$M$553,2,FALSE) -> NY6PC Nylon66 10'' 0.22µm abs. Code 3F (charge +) (86135) 2x222+plat | D2: =VLOOKUP(B2,[1]BDD!$A$4:$M$603,3,FALSE) -> F1188200 | E2: =VLOOKUP(B2,[1]BDD!$A$4:$M$603,4,FALSE) -> EFILTEC | F2: =VLOOKUP(B2,[1]BDD!$A$4:$M$603,7,FALSE) -> 123 | G2: =VLOOKUP(B2,[1]BDD!$A$4:$M$603,8,FALSE) -> 1 | H2: =VLOOKUP(B2,[1]BDD!$A$4:$M$603,9,FALSE) -> 123
B3: FILBOU1002B-7S | C3: =VLOOKUP(B3,[1]BDD!$A$4:$M$553,2,FALSE) -> EfilPore PESGA 9'' 3/4 0,2µm abs. Code 7S grade bio (97020) 2x226+baïonnette | D3: =VLOOKUP(B3,[1]BDD!$A$4:$M$603,3,FALSE) -> F1188200 | E3: =VLOOKUP(B3,[1]BDD!$A$4:$M$603,4,FALSE) -> EFILTEC | F3: =VLOOKUP(B3,[1]BDD!$A$4:$M$603,7,FALSE) -> 123 | G3: =VLOOKUP(B3,[1]BDD!$A$4:$M$603,8,FALSE) -> 1 | H3: =VLOOKUP(B3,[1]BDD!$A$4:$M$603,9,FALSE) -> 123
B4: FILBOU2002B-3S | C4: =VLOOKUP(B4,[1]BDD!$A$4:$M$553,2,FALSE) -> EfilPore PESGA 20" 0,2µm abs. Code 3F grade bio (97013) 2x222+plat | D4: =VLOOKUP(B4,[1]BDD!$A$4:$M$603,3,FALSE) -> F1188200 | E4: =VLOOKUP(B4,[1]BDD!$A$4:$M$603,4,FALSE) -> EFILTEC | F4: =VLOOKUP(B4,[1]BDD!$A$4:$M$603,7,FALSE) -> 194.75 | G4: =VLOOKUP(B4,[1]BDD!$A$4:$M$603,8,FALSE) -> 1 | H4: =VLOOKUP(B4,[1]BDD!$A$4:$M$603,9,FALSE) -> 194.75
A5: boucle | B5: FILBOU2002B-7S | C5: =VLOOKUP(B5,[1]BDD!$A$4:$M$553,2,FALSE) -> EfilPore PESGA 20" 0,2µm abs. Code 7S grade bio (97005) 2x226+baïonnette | D5: =VLOOKUP(B5,[1]BDD!$A$4:$M$603,3,FALSE) -> F1188200 | E5: =VLOOKUP(B5,[1]BDD!$A$4:$M$603,4,FALSE) -> EFILTEC | F5: =VLOOKUP(B5,[1]BDD!$A$4:$M$603,7,FALSE) -> 194.75 | G5: =VLOOKUP(B5,[1]BDD!$A$4:$M$603,8,FALSE) -> 1 | H5: =VLOOKUP(B5,[1]BDD!$A$4:$M$603,9,FALSE) -> 194.75
A7: 1 µm absolu | B7: FILABS201 | C7: =VLOOKUP(B7,[1]BDD!$A$4:$M$553,2,FALSE) -> KlariSpunGA Excel 20'' 1µm DOE EPDM (absolu) (97306) | D7: =VLOOKUP(B7,[1]BDD!$A$4:$M$603,3,FALSE) -> F1188200 | E7: =VLOOKUP(B7,[1]BDD!$A$4:$M$603,4,FALSE) -> EFILTEC | F7: =VLOOKUP(B7,[1]BDD!$A$4:$M$603,7,FALSE) -> 22.29 | G7: =VLOOKUP(B7,[1]BDD!$A$4:$M$603,8,FALSE) -> 1 | H7: =VLOOKUP(B7,[1]BDD!$A$4:$M$603,9,FALSE) -> 22.29
A8: 5 µm absolu | B8: FILABS205 | C8: =VLOOKUP(B8,[1]BDD!$A$4:$M$553,2,FALSE) -> KlariSpunGA Excel 20'' 5µm DOE EPDM (absolu) (97313) | D8: =VLOOKUP(B8,[1]BDD!$A$4:$M$603,3,FALSE) -> F1188200 | E8: =VLOOKUP(B8,[1]BDD!$A$4:$M$603,4,FALSE) -> EFILTEC | F8: =VLOOKUP(B8,[1]BDD!$A$4:$M$603,7,FALSE) -> 20.5 | G8: =VLOOKUP(B8,[1]BDD!$A$4:$M$603,8,FALSE) -> 1 | H8: =VLOOKUP(B8,[1]BDD!$A$4:$M$603,9,FALSE) -> 20.5
A10: event | B10: FILEVC05001 | C10: =VLOOKUP(B10,[1]BDD!$A$4:$M$553,2,FALSE) -> Filtre évent PTFE 5'' 0,01 µm à visser filetage 1/2" (15x21) long. 160mm (86009) | D10: =VLOOKUP(B10,[1]BDD!$A$4:$M$603,3,FALSE) -> F1188200 | E10: =VLOOKUP(B10,[1]BDD!$A$4:$M$603,4,FALSE) -> EFILTEC | F10: =VLOOKUP(B10,[1]BDD!$A$4:$M$603,7,FALSE) -> 128.13 | G10: =VLOOKUP(B10,[1]BDD!$A$4:$M$603,8,FALSE) -> 1 | H10: =VLOOKUP(B10,[1]BDD!$A$4:$M$603,9,FALSE) -> 128.13
A12: 1µm nominal | B12: FILNOM201 | C12: =VLOOKUP(B12,[1]BDD!$A$4:$M$553,2,FALSE) -> KlariSpunGA Crystal 20" 1µm DOE (nominal) (97205) | D12: =VLOOKUP(B12,[1]BDD!$A$4:$M$603,3,FALSE) -> F1188200 | E12: =VLOOKUP(B12,[1]BDD!$A$4:$M$603,4,FALSE) -> EFILTEC | F12: =VLOOKUP(B12,[1]BDD!$A$4:$M$603,7,FALSE) -> 4.07 | G12: =VLOOKUP(B12,[1]BDD!$A$4:$M$603,8,FALSE) -> 1 | H12: =VLOOKUP(B12,[1]BDD!$A$4:$M$603,9,FALSE) -> 4.07
A13: 3µm nominal | B13: FILNOM203 | C13: =VLOOKUP(B13,[1]BDD!$A$4:$M$553,2,FALSE) -> KlariSpunGA Crystal 20" 3µm DOE (nominal) (97209) | D13: =VLOOKUP(B13,[1]BDD!$A$4:$M$603,3,FALSE) -> F1188200 | E13: =VLOOKUP(B13,[1]BDD!$A$4:$M$603,4,FALSE) -> EFILTEC | F13: =VLOOKUP(B13,[1]BDD!$A$4:$M$603,7,FALSE) -> 3.97 | G13: =VLOOKUP(B13,[1]BDD!$A$4:$M$603,8,FALSE) -> 1 | H13: =VLOOKUP(B13,[1]BDD!$A$4:$M$603,9,FALSE) -> 3.97
A14: 5µm nominal | B14: FILNOM205 | C14: =VLOOKUP(B14,[1]BDD!$A$4:$M$553,2,FALSE) -> KlariSpunGA Crystal 20" 5µm DOE (nominal) (97206) | D14: =VLOOKUP(B14,[1]BDD!$A$4:$M$603,3,FALSE) -> F1188200 | E14: =VLOOKUP(B14,[1]BDD!$A$4:$M$603,4,FALSE) -> EFILTEC | F14: =VLOOKUP(B14,[1]BDD!$A$4:$M$603,7,FALSE) -> 3.97 | G14: =VLOOKUP(B14,[1]BDD!$A$4:$M$603,8,FALSE) -> 1 | H14: =VLOOKUP(B14,[1]BDD!$A$4:$M$603,9,FALSE) -> 3.97
A15: 10µm nominal | B15: FILNOM2010 | C15: =VLOOKUP(B15,[1]BDD!$A$4:$M$553,2,FALSE) -> KlariSpunGA Crystal 20" 10µm DOE (nominal) (97207) | D15: =VLOOKUP(B15,[1]BDD!$A$4:$M$603,3,FALSE) -> F1188200 | E15: =VLOOKUP(B15,[1]BDD!$A$4:$M$603,4,FALSE) -> EFILTEC | F15: =VLOOKUP(B15,[1]BDD!$A$4:$M$603,7,FALSE) -> 3.97 | G15: =VLOOKUP(B15,[1]BDD!$A$4:$M$603,8,FALSE) -> 1 | H15: =VLOOKUP(B15,[1]BDD!$A$4:$M$603,9,FALSE) -> 3.97
A16: 20µm nominal | B16: FILNOM2020 | C16: =VLOOKUP(B16,[1]BDD!$A$4:$M$553,2,FALSE) -> KlariSpunGA Crystal 20" 20µm DOE (nominal) (97200) | D16: =VLOOKUP(B16,[1]BDD!$A$4:$M$603,3,FALSE) -> F1188200 | E16: =VLOOKUP(B16,[1]BDD!$A$4:$M$603,4,FALSE) -> EFILTEC | F16: =VLOOKUP(B16,[1]BDD!$A$4:$M$603,7,FALSE) -> 3.97 | G16: =VLOOKUP(B16,[1]BDD!$A$4:$M$603,8,FALSE) -> 1 | H16: =VLOOKUP(B16,[1]BDD!$A$4:$M$603,9,FALSE) -> 3.97
A18: Coreless 5µm | B18: FILCOR405 | C18: =VLOOKUP(B18,[1]BDD!$A$4:$M$553,2,FALSE) -> Coreless Puromelt KlariSpun High Flow 40'' 5µm (74559) | D18: =VLOOKUP(B18,[1]BDD!$A$4:$M$603,3,FALSE) -> F1188200 | E18: =VLOOKUP(B18,[1]BDD!$A$4:$M$603,4,FALSE) -> EFILTEC | F18: =VLOOKUP(B18,[1]BDD!$A$4:$M$603,7,FALSE) -> 92.25 | G18: =VLOOKUP(B18,[1]BDD!$A$4:$M$603,8,FALSE) -> 1 | H18: =VLOOKUP(B18,[1]BDD!$A$4:$M$603,9,FALSE) -> 92.25
A19: Coreless 10µm | B19: FILCOR4010 | C19: =VLOOKUP(B19,[1]BDD!$A$4:$M$553,2,FALSE) -> Coreless Puromelt KlariSpun High Flow 40'' 10µm (74560) | D19: =VLOOKUP(B19,[1]BDD!$A$4:$M$603,3,FALSE) -> F1188200 | E19: =VLOOKUP(B19,[1]BDD!$A$4:$M$603,4,FALSE) -> EFILTEC | F19: =VLOOKUP(B19,[1]BDD!$A$4:$M$603,7,FALSE) -> 92.25 | G19: =VLOOKUP(B19,[1]BDD!$A$4:$M$603,8,FALSE) -> 1 | H19: =VLOOKUP(B19,[1]BDD!$A$4:$M$603,9,FALSE) -> 92.25
A20: Coreless 20µm | B20: FILCOR4020 | C20: =VLOOKUP(B20,[1]BDD!$A$4:$M$553,2,FALSE) -> Coreless Puromelt KlariSpun High Flow 40'' 20µm (74561) | D20: =VLOOKUP(B20,[1]BDD!$A$4:$M$603,3,FALSE) -> F1188200 | E20: =VLOOKUP(B20,[1]BDD!$A$4:$M$603,4,FALSE) -> EFILTEC | F20: =VLOOKUP(B20,[1]BDD!$A$4:$M$603,7,FALSE) -> 92.25 | G20: =VLOOKUP(B20,[1]BDD!$A$4:$M$603,8,FALSE) -> 1 | H20: =VLOOKUP(B20,[1]BDD!$A$4:$M$603,9,FALSE) -> 92.25
... A40: BB CA RF-Plus 5µm | B40: FILCA20BB5+ | C40: =VLOOKUP(B40,[1]BDD!$A$4:$M$553,2,FALSE) -> Pentair RF-Plus 20'' Big Blue 5µm (charbon actif + fibres synth. / réduc. chlore) (74422) | D40: =VLOOKUP(B40,[1]BDD!$A$4:$M$603,3,FALSE) -> F1188200 | E40: =VLOOKUP(B40,[1]BDD!$A$4:$M$603,4,FALSE) -> EFILTEC | F40: =VLOOKUP(B40,[1]BDD!$A$4:$M$603,7,FALSE) -> 55.22 | G40: =VLOOKUP(B40,[1]BDD!$A$4:$M$603,8,FALSE) -> 1 | H40: =VLOOKUP(B40,[1]BDD!$A$4:$M$603,9,FALSE) -> 55.22
B42: 73190 | C42: =VLOOKUP(B42,[1]BDD!$A$4:$M$553,2,FALSE) -> Joint torique Buna-N pour carters Big Blue, cartouches & poches (réf 151122) | D42: =VLOOKUP(B42,[1]BDD!$A$4:$M$603,3,FALSE) -> F1188200 | E42: =VLOOKUP(B42,[1]BDD!$A$4:$M$603,4,FALSE) -> EFILTEC | F42: =VLOOKUP(B42,[1]BDD!$A$4:$M$603,7,FALSE) -> 6.66 | G42: =VLOOKUP(B42,[1]BDD!$A$4:$M$603,8,FALSE) -> 1 | H42: =VLOOKUP(B42,[1]BDD!$A$4:$M$603,9,FALSE) -> 6.66
B43: 73197 | C43: =VLOOKUP(B43,[1]BDD!$A$4:$M$553,2,FALSE) -> Joint torique EPDM pour carters Standard & 3G (ref 151120) | D43: =VLOOKUP(B43,[1]BDD!$A$4:$M$603,3,FALSE) -> F1188200 | E43: =VLOOKUP(B43,[1]BDD!$A$4:$M$603,4,FALSE) -> EFILTEC | F43: =VLOOKUP(B43,[1]BDD!$A$4:$M$603,7,FALSE) -> 2.67 | G43: =VLOOKUP(B43,[1]BDD!$A$4:$M$603,8,FALSE) -> 1 | H43: =VLOOKUP(B43,[1]BDD!$A$4:$M$603,9,FALSE) -> 2.67
B44: ACS39EX | C44: =VLOOKUP(B44,[1]BDD!$A$4:$M$553,2,FALSE) -> Joint torique EPR 178mm pour carter EMS 3 postes (Pall) | D44: =VLOOKUP(B44,[1]BDD!$A$4:$M$603,3,FALSE) -> F1199801 | E44: =VLOOKUP(B44,[1]BDD!$A$4:$M$603,4,FALSE) -> PALL France | F44: =VLOOKUP(B44,[1]BDD!$A$4:$M$603,7,FALSE) -> 25 | G44: =VLOOKUP(B44,[1]BDD!$A$4:$M$603,8,FALSE) -> 1 | H44: =VLOOKUP(B44,[1]BDD!$A$4:$M$603,9,FALSE) -> 25
B45: ACS44EX | C45: =VLOOKUP(B45,[1]BDD!$A$4:$M$553,2,FALSE) -> Joint torique EPR 219mm pour carter EMS 5 postes (Pall) + Coreless | D45: =VLOOKUP(B45,[1]BDD!$A$4:$M$603,3,FALSE) -> F1199801 | E45: =VLOOKUP(B45,[1]BDD!$A$4:$M$603,4,FALSE) -> PALL France | F45: =VLOOKUP(B45,[1]BDD!$A$4:$M$603,7,FALSE) -> 28 | G45: =VLOOKUP(B45,[1]BDD!$A$4:$M$603,8,FALSE) -> 1 | H45: =VLOOKUP(B45,[1]BDD!$A$4:$M$603,9,FALSE) -> 28
B46: CLP-MICRO-JNT13.5 | C46: =VLOOKUP(B46,[1]BDD!$A$4:$M$553,2,FALSE) -> Joint silicoene micro clamp d25 pour tube d13.5 évent carter inox 0,2 >>> JCSIL127217 | D46: =VLOOKUP(B46,[1]BDD!$A$4:$M$603,3,FALSE) -> F1185200 | E46: =VLOOKUP(B46,[1]BDD!$A$4:$M$603,4,FALSE) -> ASEPTIC | F46: =VLOOKUP(B46,[1]BDD!$A$4:$M$603,7,FALSE) -> 11.25 | G46: =VLOOKUP(B46,[1]BDD!$A$4:$M$603,8,FALSE) -> 1.04 | H46: =VLOOKUP(B46,[1]BDD!$A$4:$M$603,9,FALSE) -> 11.7
B47: JCSIL127217 | C47: =VLOOKUP(B47,[1]BDD!$A$4:$M$553,2,FALSE) -> Joint clamp silicone 12.7-21.7 (ferrule d25) pour évent carter inox boucle type PLT12 (ex CLP-MICRO-JNT13.5) | D47: =VLOOKUP(B47,[1]BDD!$A$4:$M$603,3,FALSE) -> F1200369 | E47: =VLOOKUP(B47,[1]BDD!$A$4:$M$603,4,FALSE) -> ECO | F47: =VLOOKUP(B47,[1]BDD!$A$4:$M$603,7,FALSE) -> 5.54 | G47: =VLOOKUP(B47,[1]BDD!$A$4:$M$603,8,FALSE) -> 1.1 | H47: =VLOOKUP(B47,[1]BDD!$A$4:$M$603,9,FALSE) -> 6.094
B48: GK1242QL01 | C48: =VLOOKUP(B48,[1]BDD!$A$4:$M$553,2,FALSE) -> Joint silicone support cloche carter inox boucle type PLT12 | D48: =VLOOKUP(B48,[1]BDD!$A$4:$M$603,3,FALSE) -> F1199801 | E48: =VLOOKUP(B48,[1]BDD!$A$4:$M$603,4,FALSE) -> PALL France | F48: =VLOOKUP(B48,[1]BDD!$A$4:$M$603,7,FALSE) -> 22 | G48: =VLOOKUP(B48,[1]BDD!$A$4:$M$603,8,FALSE) -> 1 | H48: =VLOOKUP(B48,[1]BDD!$A$4:$M$603,9,FALSE) -> 22
B49: GK1344PX01 | C49: =VLOOKUP(B49,[1]BDD!$A$4:$M$553,2,FALSE) -> Joint torique EPR d'étanchéité pour carter PCY27 (Pall) | D49: =VLOOKUP(B49,[1]BDD!$A$4:$M$603,3,FALSE) -> F1199801 | E49: =VLOOKUP(B49,[1]BDD!$A$4:$M$603,4,FALSE) -> PALL France | F49: =VLOOKUP(B49,[1]BDD!$A$4:$M$603,7,FALSE) -> 22 | G49: =VLOOKUP(B49,[1]BDD!$A$4:$M$603,8,FALSE) -> 1 | H49: =VLOOKUP(B49,[1]BDD!$A$4:$M$603,9,FALSE) -> 22
B50: GK1344QL01 | C50: =VLOOKUP(B50,[1]BDD!$A$4:$M$553,2,FALSE) -> Joint torique SILICONE d'étanchéité pour carter PCY27 (Pall) | D50: =VLOOKUP(B50,[1]BDD!$A$4:$M$603,3,FALSE) -> F1199801 | E50: =VLOOKUP(B50,[1]BDD!$A$4:$M$603,4,FALSE) -> PALL France | F50: =VLOOKUP(B50,[1]BDD!$A$4:$M$603,7,FALSE) -> 22 | G50: =VLOOKUP(B50,[1]BDD!$A$4:$M$603,8,FALSE) -> 1 | H50: =VLOOKUP(B50,[1]BDD!$A$4:$M$603,9,FALSE) -> 22
B51: JCSIL254504 | C51: =VLOOKUP(B51,[1]BDD!$A$4:$M$553,2,FALSE) -> Joint clamp silicone 25.4 - 50.4 ASME BPE (Ferrule 50.4) ASME BPE | D51: =VLOOKUP(B51,[1]BDD!$A$4:$M$603,3,FALSE) -> F1200369 | E51: =VLOOKUP(B51,[1]BDD!$A$4:$M$603,4,FALSE) -> ECO | F51: =VLOOKUP(B51,[1]BDD!$A$4:$M$603,7,FALSE) -> 2.31 | G51: =VLOOKUP(B51,[1]BDD!$A$4:$M$603,8,FALSE) -> 1.04 | H51: =VLOOKUP(B51,[1]BDD!$A$4:$M$603,9,FALSE) -> 2.4024
B52: JCSIL127217 | C52: =VLOOKUP(B52,[1]BDD!$A$4:$M$553,2,FALSE) -> Joint clamp silicone 12.7-21.7 (ferrule d25) pour évent carter inox boucle type PLT12 (ex CLP-MICRO-JNT13.5) | D52: =VLOOKUP(B52,[1]BDD!$A$4:$M$603,3,FALSE) -> F1200369 | E52: =VLOOKUP(B52,[1]BDD!$A$4:$M$603,4,FALSE) -> ECO | F52: =VLOOKUP(B52,[1]BDD!$A$4:$M$603,7,FALSE) -> 5.54 | G52: =VLOOKUP(B52,[1]BDD!$A$4:$M$603,8,FALSE) -> 1.1 | H52: =VLOOKUP(B52,[1]BDD!$A$4:$M$603,9,FALSE) -> 6.094
B53: MEPDMVMI1 | C53: =VLOOKUP(B53,[1]BDD!$A$4:$M$553,2,FALSE) -> Membrane EPDM de vanne à membrane Inox 1" - 25.4 ASME BPE | D53: =VLOOKUP(B53,[1]BDD!$A$4:$M$603,3,FALSE) -> F1200369 | E53: =VLOOKUP(B53,[1]BDD!$A$4:$M$603,4,FALSE) -> ECO | F53: =VLOOKUP(B53,[1]BDD!$A$4:$M$603,7,FALSE) -> 24.39 | G53: =VLOOKUP(B53,[1]BDD!$A$4:$M$603,8,FALSE) -> 1.04 | H53: =VLOOKUP(B53,[1]BDD!$A$4:$M$603,9,FALSE) -> 25.3656
... B87: 4C.02.9.024.0050SPA | C87: =VLOOKUP(B87,[1]BDD!$A$4:$M$553,2,FALSE) -> Relais d'interface Finder 24V c.c., 2 RT, montage Rail DIN, série , 4C Series | D87: =VLOOKUP(B87,[1]BDD!$A$4:$M$603,3,FALSE) -> F1076600 | E87: =VLOOKUP(B87,[1]BDD!$A$4:$M$603,4,FALSE) -> RADIOSPARE | F87: =VLOOKUP(B87,[1]BDD!$A$4:$M$603,7,FALSE) -> 18.39 | G87: =VLOOKUP(B87,[1]BDD!$A$4:$M$603,8,FALSE) -> 1 | H87: =VLOOKUP(B87,[1]BDD!$A$4:$M$603,9,FALSE) -> 18.39
B89: ZG05SI021 | C89: =VLOOKUP(B89,[2]BDD!$A$5:$L$100,2,FALSE) -> Tuyau silicone OD 14.4x3.2 blanc (le m., par couronne de 25 m) (CeCon 3000) | D89: =VLOOKUP(B89,[2]BDD!$A$5:$L$100,3,FALSE) -> F1200373 | E89: =VLOOKUP(B89,[2]BDD!$A$5:$L$100,4,FALSE) -> DWA | F89: =VLOOKUP(B89,[2]BDD!$A$5:$L$100,7,FALSE) -> 16.373 | G89: =VLOOKUP(B89,[2]BDD!$A$5:$L$100,8,FALSE) -> 1.05 | H89: =VLOOKUP(B89,[2]BDD!$A$5:$L$100,9,FALSE) -> 17.19165 | I89: =VLOOKUP(B89,[2]BDD!$A$5:$L$100,12,FALSE) -> 2026
B90: ZG17PP954 | C90: =VLOOKUP(B90,[2]BDD!$A$5:$L$100,2,FALSE) -> Connecteur en T, PP 7,9 mm (CeCon 3000) | D90: =VLOOKUP(B90,[2]BDD!$A$5:$L$100,3,FALSE) -> F1200373 | E90: =VLOOKUP(B90,[2]BDD!$A$5:$L$100,4,FALSE) -> DWA | F90: =VLOOKUP(B90,[2]BDD!$A$5:$L$100,7,FALSE) -> 2.31441 | G90: =VLOOKUP(B90,[2]BDD!$A$5:$L$100,8,FALSE) -> 1.05 | H90: =VLOOKUP(B90,[2]BDD!$A$5:$L$100,9,FALSE) -> 2.4301305 | I90: =VLOOKUP(B90,[2]BDD!$A$5:$L$100,12,FALSE) -> 2026
B91: ZG05V9416 | C91: =VLOOKUP(B91,[2]BDD!$A$5:$L$100,2,FALSE) -> Clip 16.5, inox (CeCon 3000) | D91: =VLOOKUP(B91,[2]BDD!$A$5:$L$100,3,FALSE) -> F1200373 | E91: =VLOOKUP(B91,[2]BDD!$A$5:$L$100,4,FALSE) -> DWA | F91: =VLOOKUP(B91,[2]BDD!$A$5:$L$100,7,FALSE) -> 1.785 | G91: =VLOOKUP(B91,[2]BDD!$A$5:$L$100,8,FALSE) -> 1.05 | H91: =VLOOKUP(B91,[2]BDD!$A$5:$L$100,9,FALSE) -> 1.87425 | I91: =VLOOKUP(B91,[2]BDD!$A$5:$L$100,12,FALSE) -> 2026
B92: DN50FX8 | C92: =VLOOKUP(B92,[2]BDD!$A$5:$L$100,2,FALSE) -> DN50 F pour tuyau 8 mm (raccords BIB / CeCon 3000) | D92: =VLOOKUP(B92,[2]BDD!$A$5:$L$100,3,FALSE) -> F1200521 | E92: =VLOOKUP(B92,[2]BDD!$A$5:$L$100,4,FALSE) -> CDF Corporation | F92: =VLOOKUP(B92,[2]BDD!$A$5:$L$100,7,FALSE) -> 66.74 | G92: =VLOOKUP(B92,[2]BDD!$A$5:$L$100,8,FALSE) -> 1 | H92: =VLOOKUP(B92,[2]BDD!$A$5:$L$100,9,FALSE) -> 66.74 | I92: =VLOOKUP(B92,[2]BDD!$A$5:$L$100,12,FALSE) -> 2025

Sheet carters
A1: Carter | B1: Postes | D1: Coreless | E1: Big_Blue | F1: EMS03 | G1: EMS05 | H1: STD_Ametek | I1: PCY27
A2: Coreless | B2: 1 | D2: Coreless 5µm | E2: BB DGD 25-1µm | F2: 1µm nominal | G2: 1µm nominal | H2: 1µm nominal | I2: 1µm SOE 7S absolu
A3: Big_Blue | B3: 1 | D3: Coreless 10µm | E3: BB DGD 50-5µm | F3: 3µm nominal | G3: 3µm nominal | H3: 3µm nominal | I3: 1µm SOE 7S nominal
A4: Standard | B4: 1 | D4: Coreless 20µm | E4: BB DGD 75-25µm | F4: 5µm nominal | G4: 5µm nominal | H4: 5µm nominal | I4: 5µm SOE 7S nominal
A5: EMS_03 | B5: 3 | D5: Coreless 40µm | E5: BB CA ChlorPlus 1µm | F5: 10µm nominal | G5: 10µm nominal | H5: 10µm nominal | I5: 10µm SOE 7S nominal
A6: EMS_05 | B6: 5 | E6: BB CA RF-Plus 5µm | F6: 20µm nominal | G6: 20µm nominal | H6: 20µm nominal | I6: 20µm SOE 7S nominal
A7: PCY_27 | B7: 1 | F7: 1 µm absolu | G7: 1 µm absolu | H7: 1 µm absolu
F8: 5 µm absolu | G8: 5 µm absolu | H8: 5 µm absolu
F9: CA ChlorPlus 1µm | G9: CA ChlorPlus 1µm | H9: CA ChlorPlus 1µm
F10: CA RF-Plus 5µm | G10: CA RF-Plus 5µm | H10: CA RF-Plus 5µm
F11: Anticolloïdes 0,45µm | G11: Anticolloïdes 0,45µm | H11: Anticolloïdes 0,45µm
F12: Anticolloïdes 1µm | G12: Anticolloïdes 1µm | H12: Anticolloïdes 1µm
F13: Anticolloïdes 5µm | G13: Anticolloïdes 5µm | H13: Anticolloïdes 5µm
